<?xml version="1.0" ?>
<!-- =================================================================================== -->
<!-- |    This document was autogenerated by xacro from demo01_car_base.urdf.xacro     | -->
<!-- |    EDITING THIS FILE BY HAND IS NOT RECOMMENDED                                 | -->
<!-- =================================================================================== -->
<robot name="mycar">
  <!-- base_footprint -->
  <link name="base_footprint">
    <visual>
      <geometry>
        <sphere radius="0.001"/>
      </geometry>
    </visual>
  </link>
  <link name="base_link">
    <visual>
      <geometry>
        <cylinder length="0.08" radius="0.1"/>
      </geometry>
      <origin rpy="0 0 0" xyz="0 0 0"/>
      <material name="yellow">
        <color rgba="0.8 0.3 0.1 0.5"/>
      </material>
    </visual>
  </link>
  <joint name="base2footprint" type="fixed">
    <parent link="base_footprint"/>
    <child link="base_link"/>
    <origin rpy="0 0 0" xyz="0 0 0.055"/>
  </joint>
  <link name="drive_wheel_left">
    <visual>
      <geometry>
        <cylinder length="0.015" radius="0.0325"/>
      </geometry>
      <origin rpy="1.57079635 0 0" xyz="0 0 0"/>
      <material name="black">
        <color rgba="0 0 0 1"/>
      </material>
    </visual>
  </link>
  <joint name="drive_wheel_left_to_base" type="continuous">
    <parent link="base_link"/>
    <child link="drive_wheel_left"/>
    <origin rpy="0 0 0" xyz="0 0.1 -0.0225"/>
    <axis xyz="0 1 0"/>
  </joint>
  <link name="drive_wheel_right">
    <visual>
      <geometry>
        <cylinder length="0.015" radius="0.0325"/>
      </geometry>
      <origin rpy="1.57079635 0 0" xyz="0 0 0"/>
      <material name="black">
        <color rgba="0 0 0 1"/>
      </material>
    </visual>
  </link>
  <joint name="drive_wheel_right_to_base" type="continuous">
    <parent link="base_link"/>
    <child link="drive_wheel_right"/>
    <origin rpy="0 0 0" xyz="0 -0.1 -0.0225"/>
    <axis xyz="0 1 0"/>
  </joint>
  <link name="universal_wheel_front">
    <visual>
      <geometry>
        <sphere radius="0.0075"/>
      </geometry>
      <origin rpy="0 0 0" xyz="0 0 0"/>
      <material name="black">
        <color rgba="0 0 0 1"/>
      </material>
    </visual>
  </link>
  <joint name="universal_wheel_front_to_base" type="continuous">
    <parent link="base_link"/>
    <child link="universal_wheel_front"/>
    <origin rpy="0 0 0" xyz="0.0925 0 0.0075"/>
    <axis xyz="1 1 1"/>
  </joint>
  <link name="universal_wheel_back">
    <visual>
      <geometry>
        <sphere radius="0.0075"/>
      </geometry>
      <origin rpy="0 0 0" xyz="0 0 0"/>
      <material name="black">
        <color rgba="0 0 0 1"/>
      </material>
    </visual>
  </link>
  <joint name="universal_wheel_back_to_base" type="continuous">
    <parent link="base_link"/>
    <child link="universal_wheel_back"/>
    <origin rpy="0 0 0" xyz="-0.0925 0 0.0075"/>
    <axis xyz="1 1 1"/>
  </joint>
</robot>

